<?xml version="1.0" encoding="utf-8"?>
<!-- This URDF was automatically created by SolidWorks to URDF Exporter! Originally created by Stephen Brawner (brawner@gmail.com)
     Commit Version: 1.5.1-0-g916b5db  Build Version: 1.5.7152.31018
     For more information, please see http://wiki.ros.org/sw_urdf_exporter -->
<robot name="sra">

  <!-- ROBOT DUMMIES -->

  <link name="ArmDummyLink"/>
  <joint name="ArmDummyJoint" type="fixed">
    <origin rpy="0 0 0" xyz="0 0 0"/>
    <parent link="ArmDummyLink"/>
    <child link="ArmBaseLink"/>
  </joint>

  <!-- ROBOT LINKS -->

  <link name="ArmBaseLink">
    <inertial>
      <origin
        xyz="-3.2661E-19 -7.7765E-19 0.0127"
        rpy="0 0 0" />
      <mass value="0.08044" />
      <inertia
        ixx="2.4597E-05"
        ixy="5.9791E-38"
        ixz="-9.7646E-22"
        iyy="2.4597E-05"
        iyz="-9.765E-22"
        izz="4.0544E-05" />
    </inertial>
    <visual>
      <origin
        xyz="0 0 0"
        rpy="0 0 0" />
      <geometry>
        <mesh filename="package://srr_sim/meshes/sra/ArmBaseLink.STL" />
      </geometry>
      <material name="">
        <color rgba="0.79216 0.81961 0.93333 1" />
      </material>
    </visual>
    <collision>
      <origin
        xyz="0 0 0"
        rpy="0 0 0" />
      <geometry>
        <mesh filename="package://srr_sim/meshes/sra/ArmBaseLink.STL" />
      </geometry>
    </collision>
  </link>
  <joint name="BaseJoint" type="revolute">
    <origin
      xyz="0 0 0.073354"
      rpy="0 0 0" />
    <parent link="ArmBaseLink" />
    <child link="BaseToShoulderLink" />
    <axis xyz="0 0 1" />
    <limit
      lower="-3.14159265"
      upper="3.14159265"
      effort="125"
      velocity="0" />
  </joint>
  <link name="BaseToShoulderLink">
    <inertial>
      <origin
        xyz="-1.0922E-16 5.4252E-18 -0.029816"
        rpy="0 0 0" />
      <mass value="0.06206" />
      <inertia
        ixx="3.1832E-05"
        ixy="4.0883E-21"
        ixz="-4.1377E-21"
        iyy="2.314E-05"
        iyz="-5.8062E-21"
        izz="3.1465E-05" />
    </inertial>
    <visual>
      <origin
        xyz="0 0 0"
        rpy="0 0 0" />
      <geometry>
        <mesh filename="package://srr_sim/meshes/sra/BaseToShoulderLink.STL" />
      </geometry>
      <material name="">
        <color rgba="0.79216 0.81961 0.93333 1" />
      </material>
    </visual>
    <collision>
      <origin
        xyz="0 0 0"
        rpy="0 0 0" />
      <geometry>
        <mesh filename="package://srr_sim/meshes/sra/BaseToShoulderLink.STL" />
      </geometry>
    </collision>
  </link>
  <joint name="ShoulderJoint" type="revolute">
    <origin
      xyz="0 0 0"
      rpy="-1.5708 0 0" />
    <parent link="BaseToShoulderLink" />
    <child link="ShoulderToElbowDummyLink" />
    <axis xyz="0 0 1" />
    <limit
      lower="-3.14159265"
      upper="3.14159265"
      effort="125"
      velocity="0" />
  </joint>
  <link name="ShoulderToElbowDummyLink">
    <inertial>
      <origin
        xyz="9.5178E-09 -0.077956 1.1951E-07"
        rpy="0 0 0" />
      <mass value="0.20651" />
      <inertia
        ixx="0.00071889"
        ixy="5.7664E-11"
        ixz="-1.047E-11"
        iyy="3.5523E-05"
        iyz="2.7172E-10"
        izz="0.00071391" />
    </inertial>
    <visual>
      <origin
        xyz="0 0 0"
        rpy="0 0 0" />
      <geometry>
        <mesh filename="package://srr_sim/meshes/sra/ShoulderToElbowDummyLink.STL" />
      </geometry>
      <material name="">
        <color rgba="0.79216 0.81961 0.93333 1" />
      </material>
    </visual>
    <collision>
      <origin
        xyz="0 0 0"
        rpy="0 0 0" />
      <geometry>
        <mesh filename="package://srr_sim/meshes/sra/ShoulderToElbowDummyLink.STL" />
      </geometry>
    </collision>
  </link>
  <joint name="ElbowDummyJoint" type="fixed">
    <origin
      xyz="0 -0.19622 0"
      rpy="-1.5699 0 -1.5708" />
    <parent link="ShoulderToElbowDummyLink" />
    <child link="ElbowDummyToElbowLink" />
    <axis xyz="0 0 0" />
  </joint>
  <link name="ElbowDummyToElbowLink">
    <inertial>
      <origin
        xyz="-0.0046316 -1.6291E-19 0.013246"
        rpy="0 0 0" />
      <mass value="0.057319" />
      <inertia
        ixx="3.2017E-05"
        ixy="-2.0077E-21"
        ixz="-4.3427E-06"
        iyy="2.588E-05"
        iyz="7.1435E-21"
        izz="1.8287E-05" />
    </inertial>
    <visual>
      <origin
        xyz="0 0 0"
        rpy="0 0 0" />
      <geometry>
        <mesh filename="package://srr_sim/meshes/sra/ElbowDummyToElbowLink.STL" />
      </geometry>
      <material name="">
        <color rgba="0.79216 0.81961 0.93333 1" />
      </material>
    </visual>
    <collision>
      <origin
        xyz="0 0 0"
        rpy="0 0 0" />
      <geometry>
        <mesh filename="package://srr_sim/meshes/sra/ElbowDummyToElbowLink.STL" />
      </geometry>
    </collision>
  </link>
  <joint name="ElbowJoint" type="revolute">
    <origin
      xyz="0 0.000127 0.044653"
      rpy="1.5708 0 0" />
    <parent link="ElbowDummyToElbowLink" />
    <child link="ElbowToWristDummyLink" />
    <axis xyz="0 0 1" />
    <limit
      lower="-3.14159265"
      upper="3.14159265"
      effort="125"
      velocity="0" />
  </joint>
  <link name="ElbowToWristDummyLink">
    <inertial>
      <origin
        xyz="0.0859457002041171 -4.76514517150362E-08 -6.07913708871384E-09"
        rpy="0 0 0" />
      <mass value="0.254411955196347" />
      <inertia
        ixx="4.82915370297559E-05"
        ixy="-4.11218298859846E-10"
        ixz="-2.66009415786698E-10"
        iyy="0.00114293173407415"
        iyz="1.00207802188044E-09"
        izz="0.00113966996171655" />
    </inertial>
    <visual>
      <origin
        xyz="0 0 0"
        rpy="0 0 0" />
      <geometry>
        <mesh filename="package://srr_sim/meshes/sra/ElbowToWristDummyLink.STL" />
      </geometry>
      <material name="">
        <color rgba="0.792156862745098 0.819607843137255 0.933333333333333 1" />
      </material>
    </visual>
    <collision>
      <origin
        xyz="0 0 0"
        rpy="0 0 0" />
      <geometry>
        <mesh filename="package://srr_sim/meshes/sra/ElbowToWristDummyLink.STL" />
      </geometry>
    </collision>
  </link>
  <joint name="WristDummyJoint" type="fixed">
    <origin
      xyz="0.2267 0 0"
      rpy="0.033844 0 0.00012806" />
    <parent link="ElbowToWristDummyLink" />
    <child link="WristDummyToWristLink" />
    <axis xyz="0 0 0" />
  </joint>
  <link name="WristDummyToWristLink">
    <inertial>
      <origin
        xyz="-0.010365 1.3281E-06 -4.0549E-17"
        rpy="0 0 0" />
      <mass value="0.018159" />
      <inertia
        ixx="8.7777E-06"
        ixy="6.5632E-11"
        ixz="3.7739E-21"
        iyy="9.2899E-06"
        iyz="-1.2441E-21"
        izz="6.5965E-06" />
    </inertial>
    <visual>
      <origin
        xyz="0 0 0"
        rpy="0 0 0" />
      <geometry>
        <mesh filename="package://srr_sim/meshes/sra/WristDummyToWristLink.STL" />
      </geometry>
      <material name="">
        <color rgba="0.79216 0.81961 0.93333 1" />
      </material>
    </visual>
    <collision>
      <origin
        xyz="0 0 0"
        rpy="0 0 0" />
      <geometry>
        <mesh filename="package://srr_sim/meshes/sra/WristDummyToWristLink.STL" />
      </geometry>
    </collision>
  </link>
  <joint name="WristJoint" type="revolute">
    <origin
      xyz="0 0 0"
      rpy="0 0 -1.5708" />
    <parent link="WristDummyToWristLink" />
    <child link="WristToGripperLink" />
    <axis xyz="0 0 1" />
    <limit
      lower="-3.14159265"
      upper="3.14159265"
      effort="125"
      velocity="0" />
  </joint>
  <link name="WristToGripperLink">
    <inertial>
      <origin
        xyz="6.93889390390723E-18 0.00187028459715766 -1.51788304147971E-18"
        rpy="0 0 0" />
      <mass value="0.0640611944357688" />
      <inertia
        ixx="1.76418435994478E-05"
        ixy="4.81026205714899E-21"
        ixz="-7.94093388050907E-22"
        iyy="1.51643333221916E-05"
        iyz="2.3152009863535E-21"
        izz="1.75401124672356E-05" />
    </inertial>
    <visual>
      <origin
        xyz="0 0 0"
        rpy="0 0 0" />
      <geometry>
        <mesh filename="package://srr_sim/meshes/sra/WristToGripperLink.STL" />
      </geometry>
      <material name="">
        <color rgba="0.792156862745098 0.819607843137255 0.933333333333333 1" />
      </material>
    </visual>
    <collision>
      <origin
        xyz="0 0 0"
        rpy="0 0 0" />
      <geometry>
        <mesh filename="package://srr_sim/meshes/sra/WristToGripperLink.STL" />
      </geometry>
    </collision>
  </link>
  <joint name="GripperJoint" type="fixed">
    <origin
      xyz="0 0.0254 0.009525"
      rpy="-1.5708 0 0" />
    <parent link="WristToGripperLink" />
    <child link="GripperToFinger" />
    <axis xyz="0 0 0" />
  </joint>
  <link name="GripperToFinger">
    <inertial>
      <origin
        xyz="6.9389E-18 0.009525 -0.02353"
        rpy="0 0 0" />
      <mass value="0.064061" />
      <inertia
        ixx="1.7642E-05"
        ixy="7.9409E-22"
        ixz="1.2031E-21"
        iyy="1.754E-05"
        iyz="-3.0217E-21"
        izz="1.5164E-05" />
    </inertial>
    <visual>
      <origin
        xyz="0 0 0"
        rpy="0 0 0" />
      <geometry>
        <mesh filename="package://srr_sim/meshes/sra/GripperToFinger.STL" />
      </geometry>
      <material name="">
        <color rgba="0.79216 0.81961 0.93333 1" />
      </material>
    </visual>
    <collision>
      <origin
        xyz="0 0 0"
        rpy="0 0 0" />
      <geometry>
        <mesh filename="package://srr_sim/meshes/sra/GripperToFinger.STL" />
      </geometry>
    </collision>
  </link>
  <joint name="LFingerJoint" type="revolute">
    <origin
      xyz="-0.00762 0.009525 0.001905"
      rpy="1.5708 0.88304 0" />
    <parent link="GripperToFinger" />
    <child link="LeftFinger" />
    <axis xyz="0 0 1" />
    <limit
      lower="-3.14159265"
      upper="3.14159265"
      effort="125"
      velocity="0" />
  </joint>
  <link name="LeftFinger">
    <inertial>
      <origin
        xyz="-0.0186190688837656 0.00741270089060464 -1.89084858881472E-16"
        rpy="0 0 0" />
      <mass value="0.000346143112791696" />
      <inertia
        ixx="4.72102551979473E-08"
        ixy="1.9979772763792E-08"
        ixz="2.17548501101446E-22"
        iyy="6.13681088501549E-08"
        iyz="-5.15333521620536E-22"
        izz="4.49638260468465E-08" />
    </inertial>
    <visual>
      <origin
        xyz="0 0 0"
        rpy="0 0 0" />
      <geometry>
        <mesh filename="package://srr_sim/meshes/sra/LeftFinger.STL" />
      </geometry>
      <material name="">
        <color rgba="0.792156862745098 0.819607843137255 0.933333333333333 1" />
      </material>
    </visual>
    <collision>
      <origin
        xyz="0 0 0"
        rpy="0 0 0" />
      <geometry>
        <mesh filename="package://srr_sim/meshes/sra/LeftFinger.STL" />
      </geometry>
    </collision>
  </link>
  <joint name="RFingerJoint" type="revolute">
    <origin
      xyz="0.00762 0.009525 0.001905"
      rpy="1.5708 0.98268 -3.14159265" />
    <parent link="GripperToFinger" />
    <child link="RightFinger" />
    <axis xyz="0 0 1" />
    <limit
      lower="-3.14159265"
      upper="3.14159265"
      effort="125"
      velocity="0" />
  </joint>
  <link name="RightFinger">
    <inertial>
      <origin
        xyz="-0.018619 0.0074127 -1.5613E-17"
        rpy="0 0 0" />
      <mass value="0.00034614" />
      <inertia
        ixx="4.721E-08"
        ixy="1.998E-08"
        ixz="-3.4431E-23"
        iyy="6.1368E-08"
        iyz="-4.2807E-23"
        izz="4.4964E-08" />
    </inertial>
    <visual>
      <origin
        xyz="0 0 0"
        rpy="0 0 0" />
      <geometry>
        <mesh filename="package://srr_sim/meshes/sra/RightFinger.STL" />
      </geometry>
      <material name="">
        <color rgba="0.79216 0.81961 0.93333 1" />
      </material>
    </visual>
    <collision>
      <origin
        xyz="0 0 0"
        rpy="0 0 0" />
      <geometry>
        <mesh filename="package://srr_sim/meshes/sra/RightFinger.STL" />
      </geometry>
    </collision>
  </link>

</robot>
