<?xml version="1.0" encoding="utf-8"?>
<!-- This URDF was automatically created by SolidWorks to URDF Exporter! Originally created by Stephen Brawner (brawner@gmail.com) 
     Commit Version: 1.5.1-0-g916b5db  Build Version: 1.5.7152.31018
     For more information, please see http://wiki.ros.org/sw_urdf_exporter -->
<robot name="srr">

  <!-- ROBOT DUMMIES -->

  <link name="dummy_link"/>
  <joint name="DummyJoint" type="fixed">
    <origin rpy="0 0 0" xyz="0 0 0"/>
    <parent link="dummy_link"/>
    <child link="base_link"/>
  </joint>

  <!-- ROBOT LINKS -->

  <link name="base_link">
    <inertial>
      <origin
        xyz="-0.0511616375707918 0.0704353712452544 -1.04088218196721E-08"
        rpy="0 0 0" />
      <mass value="16.6773118924852" />
      <inertia
        ixx="0.172590277832974"
        ixy="-2.75414253705877E-09"
        ixz="0.0449381276570209"
        iyy="0.296611240719803"
        iyz="-7.04971494883016E-08"
        izz="0.387785538961407" />
    </inertial>
    <visual>
      <origin
        xyz="0 0 0"
        rpy="0 0 0" />
      <geometry>
        <mesh filename="package://srr_sim/meshes/base_link.STL" />
      </geometry>
      <material name="">
        <color rgba="0.792156862745098 0.819607843137255 0.933333333333333 1" />
      </material>
    </visual>
    <collision>
      <origin
        xyz="0 0 0"
        rpy="0 0 0" />
      <geometry>
        <mesh filename="package://srr_sim/meshes/base_link.STL" />
      </geometry>
    </collision>
  </link>
  <link name="Front_Left">
    <inertial>
      <origin
        xyz="0.08668 0.0019677 -0.01905"
        rpy="0 0 0" />
      <mass value="0.097852" />
      <inertia
        ixx="2.2243E-05"
        ixy="7.9264E-09"
        ixz="-1.9209E-21"
        iyy="0.0013778"
        iyz="1.8506E-22"
        izz="0.0013896" />
    </inertial>
    <visual>
      <origin
        xyz="0 0 0"
        rpy="0 0 0" />
      <geometry>
        <mesh filename="package://srr_sim/meshes/Front_Left.STL" />
      </geometry>
      <material name="">
        <color rgba="0.79216 0.81961 0.93333 1" />
      </material>
    </visual>
    <collision>
      <origin
        xyz="0 0 0"
        rpy="0 0 0" />
      <geometry>
        <mesh filename="package://srr_sim/meshes/Front_Left.STL" />
      </geometry>
    </collision>
  </link>
  <link name="Front_Left_Rev_Link">
    <inertial>
      <origin
        xyz="0 -0.033064 0"
        rpy="0 0 0" />
      <mass value="0.063238" />
      <inertia
        ixx="4.7373E-05"
        ixy="1.7961E-20"
        ixz="2.2235E-21"
        iyy="1.1555E-05"
        iyz="2.8067E-21"
        izz="4.9992E-05" />
    </inertial>
    <visual>
      <origin
        xyz="0 0 0"
        rpy="0 0 0" />
      <geometry>
        <mesh filename="package://srr_sim/meshes/Front_Left_Rev_Link.STL" />
      </geometry>
      <material name="">
        <color rgba="0.79216 0.81961 0.93333 1" />
      </material>
    </visual>
    <collision>
      <origin
        xyz="0 0 0"
        rpy="0 0 0" />
      <geometry>
        <mesh filename="package://srr_sim/meshes/Front_Left_Rev_Link.STL" />
      </geometry>
    </collision>
  </link>
  <link name="Front_Left_Wheel">
    <inertial>
      <origin
        xyz="5.55111512312578E-17 8.32667268468867E-17 -0.0659585874549844"
        rpy="0 0 0" />
      <mass value="0.72193847666214" />
      <inertia
        ixx="0.00217503268969959"
        ixy="-4.79844164619561E-19"
        ixz="-1.28749007982654E-18"
        iyy="0.00217503268969959"
        iyz="-2.07353665487853E-18"
        izz="0.00399122024811154" />
    </inertial>
    <visual>
      <origin
        xyz="0 0 0"
        rpy="0 0 0" />
      <geometry>
        <mesh filename="package://srr_sim/meshes/Front_Left_Wheel.STL" />
      </geometry>
      <material name="">
        <color rgba="0.79216 0.81961 0.93333 1" />
      </material>
    </visual>
    <collision>
      <origin
        xyz="0 0 0"
        rpy="0 0 0" />
      <geometry>
        <mesh filename="package://srr_sim/meshes/Front_Left_Wheel.STL" />
      </geometry>
    </collision>
  </link>
  <link name="Front_Right">
    <inertial>
      <origin
        xyz="0.0841644725318393 0.0208238283846831 0.0190500131425785"
        rpy="0 0 0" />
      <mass value="0.0978518395980198" />
      <inertia
        ixx="5.22109602469777E-05"
        ixy="-0.000149460319430953"
        ixz="-1.19430278845215E-10"
        iyy="0.000612890773966618"
        iyz="-5.22705653083454E-11"
        izz="0.000653981235525709" />
    </inertial>
    <visual>
      <origin
        xyz="0 0 0"
        rpy="0 0 0" />
      <geometry>
        <mesh filename="package://srr_sim/meshes/Front_Right.STL" />
      </geometry>
      <material name="">
        <color rgba="0.792156862745098 0.819607843137255 0.933333333333333 1" />
      </material>
    </visual>
    <collision>
      <origin
        xyz="0 0 0"
        rpy="0 0 0" />
      <geometry>
        <mesh filename="package://srr_sim/meshes/Front_Right.STL" />
      </geometry>
    </collision>
  </link>
  <link name="Front_Right_Rev_Link">
    <inertial>
      <origin
        xyz="-6.66133814775094E-16 -0.0486821054711925 0.0195531661804494"
        rpy="0 0 0" />
      <mass value="0.1436780324417" />
      <inertia
        ixx="0.000121635979212494"
        ixy="4.41083187630774E-20"
        ixz="3.60571337734315E-19"
        iyy="8.58181467246999E-05"
        iyz="1.52860469579376E-20"
        izz="6.01279888666829E-05" />
    </inertial>
    <visual>
      <origin
        xyz="0 0 0"
        rpy="0 0 0" />
      <geometry>
        <mesh filename="package://srr_sim/meshes/Front_Right_Rev_Link.STL" />
      </geometry>
      <material name="">
        <color rgba="0.792156862745098 0.819607843137255 0.933333333333333 1" />
      </material>
    </visual>
    <collision>
      <origin
        xyz="0 0 0"
        rpy="0 0 0" />
      <geometry>
        <mesh filename="package://srr_sim/meshes/Front_Right_Rev_Link.STL" />
      </geometry>
    </collision>
  </link>
  <link name="Front_Right_Wheel">
    <inertial>
      <origin
        xyz="6.9389E-17 -5.5511E-17 0.065959"
        rpy="0 0 0" />
      <mass value="0.72194" />
      <inertia
        ixx="0.002175"
        ixy="-5.6447E-21"
        ixz="1.8588E-18"
        iyy="0.002175"
        iyz="-1.0842E-19"
        izz="0.0039912" />
    </inertial>
    <visual>
      <origin
        xyz="0 0 0"
        rpy="0 0 0" />
      <geometry>
        <mesh filename="package://srr_sim/meshes/Front_Right_Wheel.STL" />
      </geometry>
      <material name="">
        <color rgba="0.79216 0.81961 0.93333 1" />
      </material>
    </visual>
    <collision>
      <origin
        xyz="0 0 0"
        rpy="0 0 0" />
      <geometry>
        <mesh filename="package://srr_sim/meshes/Front_Right_Wheel.STL" />
      </geometry>
    </collision>
  </link>
  <link name="Rear_Left">
    <inertial>
      <origin
        xyz="-0.129484101501797 -0.000479080079523499 -0.0190500000000001"
        rpy="0 0 0" />
      <mass value="0.13036735305509" />
      <inertia
        ixx="2.22512720679362E-05"
        ixy="-3.25978990830839E-06"
        ixz="-2.15250899622258E-21"
        iyy="0.00137775885904674"
        iyz="-9.1846719439127E-22"
        izz="0.00138959248730674" />
    </inertial>
    <visual>
      <origin
        xyz="0 0 0"
        rpy="0 0 0" />
      <geometry>
        <mesh filename="package://srr_sim/meshes/Rear_Left.STL" />
      </geometry>
      <material name="">
        <color rgba="0.792156862745098 0.819607843137255 0.933333333333333 1" />
      </material>
    </visual>
    <collision>
      <origin
        xyz="0 0 0"
        rpy="0 0 0" />
      <geometry>
        <mesh filename="package://srr_sim/meshes/Rear_Left.STL" />
      </geometry>
    </collision>
  </link>
  <link name="Rear_Left_Wheel">
    <inertial>
      <origin
        xyz="0.00035855 -0.00051139 -0.052821"
        rpy="0 0 0" />
      <mass value="0.69177" />
      <inertia
        ixx="0.0021208"
        ixy="1.6263E-19"
        ixz="3.5887E-20"
        iyy="0.0021208"
        iyz="-1.5005E-19"
        izz="0.0039874" />
    </inertial>
    <visual>
      <origin
        xyz="0 0 0"
        rpy="0 0 0" />
      <geometry>
        <mesh filename="package://srr_sim/meshes/Rear_Left_Wheel.STL" />
      </geometry>
      <material name="">
        <color rgba="0.79216 0.81961 0.93333 1" />
      </material>
    </visual>
    <collision>
      <origin
        xyz="0 0 0"
        rpy="0 0 0" />
      <geometry>
        <mesh filename="package://srr_sim/meshes/Rear_Left_Wheel.STL" />
      </geometry>
    </collision>
  </link>
  <link name="Rear_Right">
    <inertial>
      <origin
        xyz="-0.129455683958967 -0.00275462341653285 0.01905"
        rpy="0 0 0" />
      <mass value="0.13036735305509" />
      <inertia
        ixx="2.27844985113073E-05"
        ixy="-2.70764545199952E-05"
        ixz="4.92677162109119E-21"
        iyy="0.00137722563260337"
        iyz="2.5929948639206E-22"
        izz="0.00138959248730674" />
    </inertial>
    <visual>
      <origin
        xyz="0 0 0"
        rpy="0 0 0" />
      <geometry>
        <mesh filename="package://srr_sim/meshes/Rear_Right.STL" />
      </geometry>
      <material name="">
        <color rgba="0.792156862745098 0.819607843137255 0.933333333333333 1" />
      </material>
    </visual>
    <collision>
      <origin
        xyz="0 0 0"
        rpy="0 0 0" />
      <geometry>
        <mesh filename="package://srr_sim/meshes/Rear_Right.STL" />
      </geometry>
    </collision>
  </link>
  <link name="Rear_Right_Wheel">
    <inertial>
      <origin
        xyz="0.00205246820321092 -0.00475374418181555 0.0528212788637445"
        rpy="0 0 0" />
      <mass value="0.691773547047117" />
      <inertia
        ixx="0.00212083019020282"
        ixy="-1.11808349037568E-19"
        ixz="6.06587706562296E-20"
        iyy="0.00212083019020282"
        iyz="-1.37947198653022E-19"
        izz="0.00398741923131654" />
    </inertial>
    <visual>
      <origin
        xyz="0 0 0"
        rpy="0 0 0" />
      <geometry>
        <mesh filename="package://srr_sim/meshes/Rear_Right_Wheel.STL" />
      </geometry>
      <material name="">
        <color rgba="0.792156862745098 0.819607843137255 0.933333333333333 1" />
      </material>
    </visual>
    <collision>
      <origin
        xyz="0 0 0"
        rpy="0 0 0" />
      <geometry>
        <mesh filename="package://srr_sim/meshes/Rear_Right_Wheel.STL" />
      </geometry>
    </collision>
  </link>

  <!-- ROBOT JOINTS -->

  <joint name="FL_Joint" type="revolute">
    <origin
      xyz="0 0.15621 0.034606"
      rpy="1.5708 0 0" />
    <parent link="base_link" />
    <child link="Front_Left" />
    <axis xyz="0 0 1" />
    <limit
      lower="-1.5707963"
      upper="1.5707963"
      effort="125"
      velocity="0" />
  </joint>
  <joint name="FL_Rev_Joint" type="revolute">
    <origin
      xyz="0.21838 0.0052363 -0.01905"
      rpy="0 0.036515 0.023974" />
    <parent link="Front_Left" />
    <child link="Front_Left_Rev_Link" />
    <axis xyz="0 1 0" />
    <limit
      lower="-0.218166"
      upper="0.218166"
      effort="125"
      velocity="0" />
  </joint>
  <joint name="FL_Wheel_Joint" type="continuous">
    <origin
      xyz="0 -0.06096 0"
      rpy="0 0 -0.75345" />
    <parent link="Front_Left_Rev_Link" />
    <child link="Front_Left_Wheel" />
    <axis xyz="0 0 1" />
    <limit
      effort="12.5"
      velocity="0" />
  </joint>
  <joint name="FR_Joint" type="revolute">
    <origin
      xyz="0 -0.15621 0.034606"
      rpy="1.5708 0 0" />
    <parent link="base_link" />
    <child link="Front_Right" />
    <axis xyz="0 0 1" />
    <limit
      lower="-1.5707963"
      upper="1.5707963"
      effort="125"
      velocity="0" />
  </joint>
  <joint name="FR_Rev_Joint" type="revolute">
    <origin
      xyz="0.21198 0.052735 0.01905"
      rpy="0 -0.0080108 0.24382" />
    <parent link="Front_Right" />
    <child link="Front_Right_Rev_Link" />
    <axis xyz="0 1 0" />
    <limit
      lower="-0.218166"
      upper="0.218166"
      effort="125"
      velocity="0" />
  </joint>
  <joint name="FR_Wheel_Joint" type="continuous">
    <origin
      xyz="0 -0.06096 0"
      rpy="0 0 -1.311" />
    <parent link="Front_Right_Rev_Link" />
    <child link="Front_Right_Wheel" />
    <axis xyz="0 0 1" />
    <limit
      effort="12.5"
      velocity="0" />
  </joint>
  <joint name="RL_Joint" type="revolute">
    <origin
      xyz="0 0.18161 0.034606"
      rpy="1.5708 0 0" />
    <parent link="base_link" />
    <child link="Rear_Left" />
    <axis xyz="0 0 1" />
    <limit
      lower="-1.5707963"
      upper="1.5707963"
      effort="125"
      velocity="0" />
  </joint>
  <joint name="RL_Wheel_Joint" type="continuous">
    <origin
      xyz="-0.25908 0 0"
      rpy="0 0 -0.61027" />
    <parent link="Rear_Left" />
    <child link="Rear_Left_Wheel" />
    <axis xyz="0 0 1" />
    <limit
      effort="12.5"
      velocity="0" />
  </joint>
  <joint name="RR_Joint" type="revolute">
    <origin
      xyz="0 -0.18161 0.0346062035203441"
      rpy="1.5707963267949 0 0" />
    <parent link="base_link" />
    <child link="Rear_Right" />
    <axis xyz="0 0 1" />
    <limit
      lower="-1.5707963"
      upper="1.5707963"
      effort="125"
      velocity="0" />
  </joint>
  <joint name="RR_Wheel_Joint" type="continuous">
    <origin
      xyz="-0.25908 0 0"
      rpy="0 0 -0.39759" />
    <parent link="Rear_Right" />
    <child link="Rear_Right_Wheel" />
    <axis xyz="0 0 1" />
    <limit
      effort="12.5"
      velocity="0" />
  </joint>

</robot>
