<?xml version="1.0" encoding="utf-8"?>
<!-- This URDF was automatically created by SolidWorks to URDF Exporter! Originally created by Stephen Brawner (brawner@gmail.com) 
     Commit Version: 1.5.1-0-g916b5db  Build Version: 1.5.7152.31018
     For more information, please see http://wiki.ros.org/sw_urdf_exporter -->
<robot name="srr">

  <!-- ROBOT DUMMIES -->

  <link name="VehicleDummyLink"/>
  <joint name="VehicleDummyJoint" type="fixed">
    <origin rpy="0 0 0" xyz="0 0 0"/>
    <parent link="VehicleDummyLink"/>
    <child link="Vehicle_Base_Link"/>
  </joint>

  <!-- ROBOT LINKS -->

  <link name="Vehicle_Base_Link">
    <inertial>
      <origin
        xyz="-0.05113081011494 1.04025499845068E-08 0.0704137823724448"
        rpy="0 0 0" />
      <mass value="16.6873668690236" />
      <inertia
        ixx="0.172590277832974"
        ixy="-2.75414253598103E-09"
        ixz="0.0449381276570209"
        iyy="0.296611240719803"
        iyz="-7.04971494872995E-08"
        izz="0.387785538961407" />
    </inertial>
    <visual>
      <origin
        xyz="0 0 0"
        rpy="0 0 0" />
      <geometry>
        <mesh filename="package://srr_sim/meshes/srr/Vehicle_Base_Link.STL" />
      </geometry>
      <material name="">
        <color rgba="0.792156862745098 0.819607843137255 0.933333333333333 1" />
      </material>
    </visual>
    <collision>
      <origin
        xyz="0 0 0"
        rpy="0 0 0" />
      <geometry>
        <mesh filename="package://srr_sim/meshes/srr/Vehicle_Base_Link.STL" />
      </geometry>
    </collision>
  </link>
  <link name="Front_Left">
    <inertial>
      <origin
        xyz="0.0867022465337713 -0.000110737937059305 -0.0222249908508295"
        rpy="0 0 0" />
      <mass value="0.0978518500972839" />
      <inertia
        ixx="1.48585915953864E-05"
        ixy="-6.85387621510374E-07"
        ixz="-9.11737076552848E-11"
        iyy="0.000650243209338264"
        iyz="-1.20002153680288E-11"
        izz="0.000653981315600044" />
    </inertial>
    <visual>
      <origin
        xyz="0 0 0"
        rpy="0 0 0" />
      <geometry>
        <mesh filename="package://srr_sim/meshes/srr/Front_Left.STL" />
      </geometry>
      <material name="">
        <color rgba="0.792156862745098 0.819607843137255 0.933333333333333 1" />
      </material>
    </visual>
    <collision>
      <origin
        xyz="0 0 0"
        rpy="0 0 0" />
      <geometry>
        <mesh filename="package://srr_sim/meshes/srr/Front_Left.STL" />
      </geometry>
    </collision>
  </link>
  <link name="Front_Left_Rev_Link">
    <inertial>
      <origin
        xyz="0 -0.0330644690274216 0"
        rpy="0 0 0" />
      <mass value="0.0632382201349724" />
      <inertia
        ixx="4.73725577420752E-05"
        ixy="-3.86235636495354E-20"
        ixz="-1.05879118406788E-21"
        iyy="1.15547252542813E-05"
        iyz="4.08826156182325E-21"
        izz="4.99919440800016E-05" />
    </inertial>
    <visual>
      <origin
        xyz="0 0 0"
        rpy="0 0 0" />
      <geometry>
        <mesh filename="package://srr_sim/meshes/srr/Front_Left_Rev_Link.STL" />
      </geometry>
      <material name="">
        <color rgba="0.792156862745098 0.819607843137255 0.933333333333333 1" />
      </material>
    </visual>
    <collision>
      <origin
        xyz="0 0 0"
        rpy="0 0 0" />
      <geometry>
        <mesh filename="package://srr_sim/meshes/srr/Front_Left_Rev_Link.STL" />
      </geometry>
    </collision>
  </link>
  <link name="Front_Left_Wheel">
    <inertial>
      <origin
        xyz="-9.71445146547012E-17 0 -0.0659585874549852"
        rpy="0 0 0" />
      <mass value="0.72193847666214" />
      <inertia
        ixx="0.0021750326896996"
        ixy="1.04605260263456E-19"
        ixz="1.40480414302126E-18"
        iyy="0.00217503268969959"
        iyz="1.1418004128988E-18"
        izz="0.00399122024811154" />
    </inertial>
    <visual>
      <origin
        xyz="0 0 0"
        rpy="0 0 0" />
      <geometry>
        <mesh filename="package://srr_sim/meshes/srr/Front_Left_Wheel.STL" />
      </geometry>
      <material name="">
        <color rgba="0.79216 0.81961 0.93333 1" />
      </material>
    </visual>
    <collision>
      <origin
        xyz="0 0 0"
        rpy="0 0 0" />
      <geometry>
        <mesh filename="package://srr_sim/meshes/srr/Front_Left_Wheel.STL" />
      </geometry>
    </collision>
  </link>
  <link name="Front_Right">
    <inertial>
      <origin
        xyz="0.0867022469755965 -0.000110738102431042 0.022225008970637"
        rpy="0 0 0" />
      <mass value="0.0978518506132432" />
      <inertia
        ixx="1.48585915440963E-05"
        ixy="-6.85385988492656E-07"
        ixz="-8.95060719518691E-11"
        iyy="0.000650243212819492"
        iyz="-1.15669956708496E-11"
        izz="0.000653981319565328" />
    </inertial>
    <visual>
      <origin
        xyz="0 0 0"
        rpy="0 0 0" />
      <geometry>
        <mesh filename="package://srr_sim/meshes/srr/Front_Right.STL" />
      </geometry>
      <material name="">
        <color rgba="0.792156862745098 0.819607843137255 0.933333333333333 1" />
      </material>
    </visual>
    <collision>
      <origin
        xyz="0 0 0"
        rpy="0 0 0" />
      <geometry>
        <mesh filename="package://srr_sim/meshes/srr/Front_Right.STL" />
      </geometry>
    </collision>
  </link>
  <link name="Front_Right_Rev_Link">
    <inertial>
      <origin
        xyz="0 -0.0330644690274216 0"
        rpy="0 0 0" />
      <mass value="0.0632382201349724" />
      <inertia
        ixx="4.73725577420752E-05"
        ixy="-3.86234591938486E-20"
        ixz="-1.05879118406788E-21"
        iyy="1.15547252542813E-05"
        iyz="4.08495448860633E-21"
        izz="4.99919440800016E-05" />
    </inertial>
    <visual>
      <origin
        xyz="0 0 0"
        rpy="0 0 0" />
      <geometry>
        <mesh filename="package://srr_sim/meshes/srr/Front_Right_Rev_Link.STL" />
      </geometry>
      <material name="">
        <color rgba="0.792156862745098 0.819607843137255 0.933333333333333 1" />
      </material>
    </visual>
    <collision>
      <origin
        xyz="0 0 0"
        rpy="0 0 0" />
      <geometry>
        <mesh filename="package://srr_sim/meshes/srr/Front_Right_Rev_Link.STL" />
      </geometry>
    </collision>
  </link>
  <link name="Front_Right_Wheel">
    <inertial>
      <origin
        xyz="-1.38777878078145E-17 -2.77555756156289E-17 0.065958587454985"
        rpy="0 0 0" />
      <mass value="0.721938476662141" />
      <inertia
        ixx="0.0021750326896996"
        ixy="-2.35686917573509E-19"
        ixz="-9.62229428080885E-19"
        iyy="0.0021750326896996"
        iyz="1.00288700954909E-18"
        izz="0.00399122024811155" />
    </inertial>
    <visual>
      <origin
        xyz="0 0 0"
        rpy="0 0 0" />
      <geometry>
        <mesh filename="package://srr_sim/meshes/srr/Front_Right_Wheel.STL" />
      </geometry>
      <material name="">
        <color rgba="0.792156862745098 0.819607843137255 0.933333333333333 1" />
      </material>
    </visual>
    <collision>
      <origin
        xyz="0 0 0"
        rpy="0 0 0" />
      <geometry>
        <mesh filename="package://srr_sim/meshes/srr/Front_Right_Wheel.STL" />
      </geometry>
    </collision>
  </link>
  <link name="Rear_Left">
    <inertial>
      <origin
        xyz="0.08670224665642 -0.000110755562457591 -0.0222250029970638"
        rpy="0 0 0" />
      <mass value="0.097851850152702" />
      <inertia
        ixx="1.48585913794711E-05"
        ixy="-6.85222917824611E-07"
        ixz="3.03270696730864E-11"
        iyy="0.000650243211545947"
        iyz="-1.23431571637755E-11"
        izz="0.000653981316743633" />
    </inertial>
    <visual>
      <origin
        xyz="0 0 0"
        rpy="0 0 0" />
      <geometry>
        <mesh filename="package://srr_sim/meshes/srr/Rear_Left.STL" />
      </geometry>
      <material name="">
        <color rgba="0.792156862745098 0.819607843137255 0.933333333333333 1" />
      </material>
    </visual>
    <collision>
      <origin
        xyz="0 0 0"
        rpy="0 0 0" />
      <geometry>
        <mesh filename="package://srr_sim/meshes/srr/Rear_Left.STL" />
      </geometry>
    </collision>
  </link>
  <link name="Rear_Left_Fixed_Link">
    <inertial>
      <origin
        xyz="0 -0.016554 0"
        rpy="0 0 0" />
      <mass value="0.063238" />
      <inertia
        ixx="4.7373E-05"
        ixy="1.44E-20"
        ixz="-1.6356E-22"
        iyy="1.1555E-05"
        iyz="1.1572E-21"
        izz="4.9992E-05" />
    </inertial>
    <visual>
      <origin
        xyz="0 0 0"
        rpy="0 0 0" />
      <geometry>
        <mesh filename="package://srr_sim/meshes/srr/Rear_Left_Fixed_Link.STL" />
      </geometry>
      <material name="">
        <color rgba="0.79216 0.81961 0.93333 1" />
      </material>
    </visual>
    <collision>
      <origin
        xyz="0 0 0"
        rpy="0 0 0" />
      <geometry>
        <mesh filename="package://srr_sim/meshes/srr/Rear_Left_Fixed_Link.STL" />
      </geometry>
    </collision>
  </link>
  <link name="Rear_Left_Wheel">
    <inertial>
      <origin
        xyz="2.77555756156289E-17 -2.77555756156289E-17 -0.0659585874549843"
        rpy="0 0 0" />
      <mass value="0.72193847666214" />
      <inertia
        ixx="0.00217503268969959"
        ixy="-1.0842021724855E-18"
        ixz="-3.29297393714089E-19"
        iyy="0.00217503268969959"
        iyz="-1.00931628617887E-19"
        izz="0.00399122024811154" />
    </inertial>
    <visual>
      <origin
        xyz="0 0 0"
        rpy="0 0 0" />
      <geometry>
        <mesh filename="package://srr_sim/meshes/srr/Rear_Left_Wheel.STL" />
      </geometry>
      <material name="">
        <color rgba="0.792156862745098 0.819607843137255 0.933333333333333 1" />
      </material>
    </visual>
    <collision>
      <origin
        xyz="0 0 0"
        rpy="0 0 0" />
      <geometry>
        <mesh filename="package://srr_sim/meshes/srr/Rear_Left_Wheel.STL" />
      </geometry>
    </collision>
  </link>
  <link name="Rear_Right">
    <inertial>
      <origin
        xyz="0.0867022466707873 -0.000110755556609228 0.022224997009222"
        rpy="0 0 0" />
      <mass value="0.0978518501695887" />
      <inertia
        ixx="1.48585913776131E-05"
        ixy="-6.85222975533347E-07"
        ixz="3.0268368356874E-11"
        iyy="0.000650243211657407"
        iyz="-1.23282905187147E-11"
        izz="0.000653981316872298" />
    </inertial>
    <visual>
      <origin
        xyz="0 0 0"
        rpy="0 0 0" />
      <geometry>
        <mesh filename="package://srr_sim/meshes/srr/Rear_Right.STL" />
      </geometry>
      <material name="">
        <color rgba="0.792156862745098 0.819607843137255 0.933333333333333 1" />
      </material>
    </visual>
    <collision>
      <origin
        xyz="0 0 0"
        rpy="0 0 0" />
      <geometry>
        <mesh filename="package://srr_sim/meshes/srr/Rear_Right.STL" />
      </geometry>
    </collision>
  </link>
  <link name="Rear_Right_Fixed_Link">
    <inertial>
      <origin
        xyz="-2.77555756156289E-17 -0.0165544690274212 0"
        rpy="0 0 0" />
      <mass value="0.0632382201349725" />
      <inertia
        ixx="4.73725577420752E-05"
        ixy="2.96461531539005E-20"
        ixz="-4.72365825490173E-22"
        iyy="1.15547252542813E-05"
        iyz="-2.01510564995318E-21"
        izz="4.99919440800016E-05" />
    </inertial>
    <visual>
      <origin
        xyz="0 0 0"
        rpy="0 0 0" />
      <geometry>
        <mesh filename="package://srr_sim/meshes/srr/Rear_Right_Fixed_Link.STL" />
      </geometry>
      <material name="">
        <color rgba="0.792156862745098 0.819607843137255 0.933333333333333 1" />
      </material>
    </visual>
    <collision>
      <origin
        xyz="0 0 0"
        rpy="0 0 0" />
      <geometry>
        <mesh filename="package://srr_sim/meshes/srr/Rear_Right_Fixed_Link.STL" />
      </geometry>
    </collision>
  </link>
  <link name="Rear_Right_Wheel">
    <inertial>
      <origin
        xyz="-2.7756E-17 6.9389E-18 0.065959"
        rpy="0 0 0" />
      <mass value="0.72194" />
      <inertia
        ixx="0.002175"
        ixy="-2.7105E-19"
        ixz="2.0798E-19"
        iyy="0.002175"
        iyz="1.0374E-19"
        izz="0.0039912" />
    </inertial>
    <visual>
      <origin
        xyz="0 0 0"
        rpy="0 0 0" />
      <geometry>
        <mesh filename="package://srr_sim/meshes/srr/Rear_Right_Wheel.STL" />
      </geometry>
      <material name="">
        <color rgba="0.79216 0.81961 0.93333 1" />
      </material>
    </visual>
    <collision>
      <origin
        xyz="0 0 0"
        rpy="0 0 0" />
      <geometry>
        <mesh filename="package://srr_sim/meshes/srr/Rear_Right_Wheel.STL" />
      </geometry>
    </collision>
  </link>

  <!-- ROBOT JOINTS -->
  <!-- Assumed a range of motion for each chassis elevation joint to be [0, 44] degrees -->
  <!--    "    "   "   "     "    "    "  front wheel's steering to be [-15, 15] degrees -->

  <joint name="FL_Joint" type="revolute">
    <origin
      xyz="0 0.15304 0.034606"
      rpy="1.5708 0 0" />
    <parent link="Vehicle_Base_Link" />
    <child link="Front_Left" />
    <axis xyz="0 0 1" />
    <limit
      lower="-0.767945"
      upper="0.0"
      effort="125"
      velocity="1.25" />
  </joint>
  <joint name="FL_Rev_Joint" type="revolute">
    <origin
      xyz="0.21844 0 -0.022225"
      rpy="0 -0.0077095 0" />
    <parent link="Front_Left" />
    <child link="Front_Left_Rev_Link" />
    <axis xyz="0 1 0" />
    <limit
      lower="-0.2618"
      upper="0.2618"
      effort="125"
      velocity="0" />
  </joint>
  <joint name="FL_Wheel_Joint" type="continuous">
    <origin
      xyz="0 -0.06096 0"
      rpy="0 0 0" />
    <parent link="Front_Left_Rev_Link" />
    <child link="Front_Left_Wheel" />
    <axis xyz="0 0 1" />
    <limit
      effort="12.5"
      velocity="2.5" />
  </joint>
  <joint name="FR_Joint" type="revolute">
    <origin
      xyz="0 -0.153035 0.0346062035203441"
      rpy="1.5707963267949 0 0" />
    <parent link="Vehicle_Base_Link" />
    <child link="Front_Right" />
    <axis xyz="0 0 1" />
    <limit
      lower="-0.767945"
      upper="0.0"
      effort="125"
      velocity="1.25" />
  </joint>
  <joint name="FR_Rev_Joint" type="revolute">
    <origin
      xyz="0.21844 0 0.022225"
      rpy="0 0.031575 0" />
    <parent link="Front_Right" />
    <child link="Front_Right_Rev_Link" />
    <axis xyz="0 1 0" />
    <limit
      lower="-0.2618"
      upper="0.2618"
      effort="125"
      velocity="0" />
  </joint>
  <joint name="FR_Wheel_Joint" type="continuous">
    <origin
      xyz="0 -0.06096 0"
      rpy="0 0 0" />
    <parent link="Front_Right_Rev_Link" />
    <child link="Front_Right_Wheel" />
    <axis xyz="0 0 1" />
    <limit
      effort="12.5"
      velocity="2.5" />
  </joint>
  <joint name="RL_Joint" type="revolute">
    <origin
      xyz="0 0.17844 0.034606"
      rpy="-1.5708 0 -3.1416" />
    <parent link="Vehicle_Base_Link" />
    <child link="Rear_Left" />
    <axis xyz="0 0 1" />
    <limit
      lower="0.0"
      upper="0.767945"
      effort="125"
      velocity="1.25" />
  </joint>
  <joint name="RL_Fixed_Joint" type="fixed">
    <origin
      xyz="0.21844 0.01651 -0.022225"
      rpy="0 0 3.1416" />
    <parent link="Rear_Left" />
    <child link="Rear_Left_Fixed_Link" />
    <axis xyz="0 0 0" />
  </joint>
  <joint name="RL_Wheel_Joint" type="continuous">
    <origin
      xyz="0 -0.04445 0"
      rpy="0 0 0" />
    <parent link="Rear_Left_Fixed_Link" />
    <child link="Rear_Left_Wheel" />
    <axis xyz="0 0 1" />
    <limit
      effort="12.5"
      velocity="2.5" />
  </joint>
  <joint name="RR_Joint" type="revolute">
    <origin
      xyz="0 -0.17844 0.034606"
      rpy="-1.5708 0 -3.1416" />
    <parent link="Vehicle_Base_Link" />
    <child link="Rear_Right" />
    <axis xyz="0 0 1" />
    <limit
      lower="0.0"
      upper="0.767945"
      effort="125"
      velocity="1.25" />
  </joint>
  <joint name="RR_Fixed_Joint" type="fixed">
    <origin
      xyz="0.21844 0.01651 0.022225"
      rpy="0 0 3.1416" />
    <parent link="Rear_Right" />
    <child link="Rear_Right_Fixed_Link" />
    <axis xyz="0 0 0" />
  </joint>
  <joint name="RR_Wheel_Joint" type="continuous">
    <origin
      xyz="0 -0.04445 0"
      rpy="0 0 0" />
    <parent link="Rear_Right_Fixed_Link" />
    <child link="Rear_Right_Wheel" />
    <axis xyz="0 0 1" />
    <limit
      effort="12.5"
      velocity="2.5" />
  </joint>

</robot>
